<?xml version="1.0" ?>
<!-- =================================================================================== -->
<!-- |    This document was autogenerated by xacro from spot_7dof_psyonic_no_base.urdf.xacro | -->
<!-- |    EDITING THIS FILE BY HAND IS NOT RECOMMENDED                                 | -->
<!-- =================================================================================== -->
<robot name="papras_psyonic_spot">
  <!-- left arm prefix is robot1/ -->
  <!-- right arm prefix is robot2/ -->
  <!-- PAPRAS URDF Macros -->
  <!-- Main URDF File should contain:
        - world link
        - world-env joint
        - env link
        - env-robotn/link1 joint for each mount -->
  <!-- This file contains URDF geometry, transmission data and Gazebo references -->
  <material name="black">
    <color rgba="0.0 0.0 0.0 1.0"/>
  </material>
  <material name="blue">
    <color rgba="0.0 0.0 0.8 1.0"/>
  </material>
  <material name="green">
    <color rgba="0.0 0.8 0.0 1.0"/>
  </material>
  <material name="grey">
    <color rgba="0.5 0.5 0.5 1.0"/>
  </material>
  <material name="orange">
    <color rgba="1.0 0.4235294117647059 0.0392156862745098 1.0"/>
  </material>
  <material name="brown">
    <color rgba="0.8705882352941177 0.8117647058823529 0.7647058823529411 1.0"/>
  </material>
  <material name="red">
    <color rgba="0.8 0.0 0.0 1.0"/>
  </material>
  <material name="white">
    <color rgba="1.0 1.0 1.0 1.0"/>
  </material>
  <!-- Import all Gazebo-customization elements, including Gazebo colors -->
  <!-- World -->
  <gazebo reference="world"/>
  <!-- Evn Link -->
  <gazebo reference="env"/>
  <!-- ros_control plugin -->
  <gazebo>
    <plugin filename="libgazebo_ros_control.so" name="gazebo_ros_control">
      <robotSimType>gazebo_ros_control/DefaultRobotHWSim</robotSimType>
    </plugin>
  </gazebo>
  <mujoco>
    <compiler angle="radian" autolimits="true" balanceinertia="true" discardvisual="false" fusestatic="false" meshdir="../assets/" strippath="false"/>
  </mujoco>
  <!-- <link name="world"/> -->
  <link name="env">
    <visual>
      <origin rpy="0 0 0" xyz="0.0 0.0 0.0"/>
      <geometry>
        <mesh filename="/home/sankalp/ws_spot_catching/src/BimanualDexCatch/assets/urdf/spot_description/meshes/spot_mount.stl"/>
      </geometry>
      <material name="grey"/>
    </visual>
    <collision>
      <origin rpy="0 0 0" xyz="0.0 0.0 0.0"/>
      <geometry>
        <mesh filename="/home/sankalp/ws_spot_catching/src/BimanualDexCatch/assets/urdf/spot_description/meshes/spot_mount.stl"/>
      </geometry>
    </collision>
  </link>
  <gazebo reference="env">
    <self_collide>0</self_collide>
  </gazebo>
  <joint name="robot1/env_arm_fixed" type="fixed">
    <parent link="env"/>
    <child link="robot1/link1"/>
    <origin rpy="0 -0.7853981633974483 4.71238898038469" xyz="0.0 0.05049 0.09003"/>
  </joint>
  <joint name="robot2/env_arm_fixed" type="fixed">
    <parent link="env"/>
    <child link="robot2/link1"/>
    <origin rpy="0 -0.7853981633974483 1.5707963267948966" xyz="0.0 -0.05049 0.09003"/>
  </joint>
  <!-- link 1 -->
  <link name="robot1/link1">
    <visual>
      <origin rpy="0 0 0" xyz="0 0 0"/>
      <geometry>
        <mesh filename="/home/sankalp/ws_spot_catching/src/BimanualDexCatch/assets/urdf/spot_description/meshes/link1.stl" scale="0.001 0.001 0.001"/>
      </geometry>
      <material name="grey"/>
    </visual>
    <collision>
      <origin rpy="0 0 0" xyz="0 0 0"/>
      <geometry>
        <mesh filename="/home/sankalp/ws_spot_catching/src/BimanualDexCatch/assets/urdf/spot_description/meshes/link1.stl" scale="0.001 0.001 0.001"/>
      </geometry>
    </collision>
    <inertial>
      <origin xyz="-0.00205616406 0.00000000 0.07012969338"/>
      <mass value="0.91200000"/>
      <inertia ixx="0.00140582306367" ixy="0.00000000" ixz="0.00000000" iyy="0.00140582097352" iyz="-0.00000000" izz="0.00043779331105"/>
    </inertial>
  </link>
  <gazebo reference="robot1/link1">
    <kp>1000000.0</kp>
    <kd>100.0</kd>
    <mu1>30.0</mu1>
    <mu2>30.0</mu2>
    <maxVel>1.0</maxVel>
    <minDepth>0.001</minDepth>
    <material>Gazebo/White</material>
    <selfCollide>1</selfCollide>
    <dampingFactor>0.01</dampingFactor>
  </gazebo>
  <!-- Joint 1 -->
  <joint name="robot1/joint1" type="revolute">
    <parent link="robot1/link1"/>
    <child link="robot1/link2"/>
    <origin rpy="0 0 0" xyz="0.0 0.0 0.126"/>
    <axis xyz="0 0 1"/>
    <limit effort="100" lower="-3.141592653589793" upper="3.141592653589793" velocity="3.03687"/>
    <dynamics damping="0.7"/>
  </joint>
  <transmission name="robot1/tran1">
    <type>transmission_interface/SimpleTransmission</type>
    <joint name="robot1/joint1">
      <hardwareInterface>hardware_interface/PositionJointInterface</hardwareInterface>
    </joint>
    <actuator name="robot1/motor1">
      <mechanicalReduction>1</mechanicalReduction>
    </actuator>
  </transmission>
  <!-- link 2 -->
  <link name="robot1/link2">
    <visual>
      <origin rpy="0 0 0" xyz="0 0 0"/>
      <geometry>
        <mesh filename="/home/sankalp/ws_spot_catching/src/BimanualDexCatch/assets/urdf/spot_description/meshes/link2.stl" scale="0.001 0.001 0.001"/>
      </geometry>
      <material name="grey"/>
    </visual>
    <collision>
      <origin rpy="0 0 0" xyz="0 0 0"/>
      <geometry>
        <mesh filename="/home/sankalp/ws_spot_catching/src/BimanualDexCatch/assets/urdf/spot_description/meshes/link2.stl" scale="0.001 0.001 0.001"/>
      </geometry>
    </collision>
    <inertial>
      <origin xyz="-0.00000000001 -0.01570756882 0.02819237930"/>
      <mass value="0.88500000"/>
      <inertia ixx="0.00155754725347" ixy="-0.00000000" ixz="-0.00000000" iyy="0.00048405544236" iyz="-0.00000173296990" izz="0.00154667193282"/>
    </inertial>
  </link>
  <gazebo reference="robot1/link2">
    <kp>1000000.0</kp>
    <kd>100.0</kd>
    <mu1>30.0</mu1>
    <mu2>30.0</mu2>
    <maxVel>1.0</maxVel>
    <minDepth>0.001</minDepth>
    <material>Gazebo/White</material>
    <selfCollide>1</selfCollide>
    <dampingFactor>0.01</dampingFactor>
  </gazebo>
  <!-- Joint 2 -->
  <joint name="robot1/joint2" type="revolute">
    <parent link="robot1/link2"/>
    <child link="robot1/link3"/>
    <origin rpy="1.5707963267948966 -1.5707963267948966 0" xyz="0.0 0.00 0.033"/>
    <axis xyz="0 0 1"/>
    <limit effort="100" lower="-2.0" upper="2.0" velocity="3.03687"/>
    <dynamics damping="0.7"/>
  </joint>
  <transmission name="robot1/tran2">
    <type>transmission_interface/SimpleTransmission</type>
    <joint name="robot1/joint2">
      <hardwareInterface>hardware_interface/PositionJointInterface</hardwareInterface>
    </joint>
    <actuator name="robot1/motor2">
      <mechanicalReduction>1</mechanicalReduction>
    </actuator>
  </transmission>
  <!-- link 2 -->
  <link name="robot1/link3">
    <visual>
      <origin rpy="0 0 0" xyz="0.0 0.0 0.0"/>
      <geometry>
        <mesh filename="/home/sankalp/ws_spot_catching/src/BimanualDexCatch/assets/urdf/spot_description/meshes/7dof/link3.stl"/>
      </geometry>
      <material name="grey"/>
    </visual>
    <collision>
      <origin rpy="0 0 0" xyz="0 0 0"/>
      <geometry>
        <mesh filename="/home/sankalp/ws_spot_catching/src/BimanualDexCatch/assets/urdf/spot_description/meshes/7dof/link3.stl"/>
      </geometry>
    </collision>
    <inertial>
      <origin xyz="0.10300488 0.00026160 0.00111164"/>
      <mass value="1.01000000"/>
      <inertia ixx="0.00182373" ixy="-0.00000000" ixz="-0.00000526" iyy="0.00433189" iyz="0.00000000" izz="0.00310084"/>
    </inertial>
  </link>
  <gazebo reference="robot1/link3">
    <kp>1000000.0</kp>
    <kd>100.0</kd>
    <mu1>30.0</mu1>
    <mu2>30.0</mu2>
    <maxVel>1.0</maxVel>
    <minDepth>0.001</minDepth>
    <material>Gazebo/White</material>
    <selfCollide>1</selfCollide>
    <dampingFactor>0.01</dampingFactor>
  </gazebo>
  <!-- Joint 2 -->
  <joint name="robot1/joint3" type="revolute">
    <parent link="robot1/link3"/>
    <child link="robot1/link4"/>
    <origin rpy="0 -1.5707963267948966 -1.5707963267948966" xyz="0.156382198147594 0 0.000400000000010851"/>
    <axis xyz="0 1 0"/>
    <limit effort="100" lower="-3.141592653589793" upper="3.141592653589793" velocity="3.03687"/>
    <dynamics damping="0.7"/>
  </joint>
  <transmission name="robot1/tran3">
    <type>transmission_interface/SimpleTransmission</type>
    <joint name="robot1/joint3">
      <hardwareInterface>hardware_interface/PositionJointInterface</hardwareInterface>
    </joint>
    <actuator name="robot1/motor3">
      <mechanicalReduction>1</mechanicalReduction>
    </actuator>
  </transmission>
  <!-- link 2 -->
  <link name="robot1/link4">
    <visual>
      <origin rpy="0 0 0" xyz="0.0 0.0 0.0"/>
      <geometry>
        <mesh filename="/home/sankalp/ws_spot_catching/src/BimanualDexCatch/assets/urdf/spot_description/meshes/7dof/link4.stl"/>
      </geometry>
      <material name="grey"/>
    </visual>
    <collision>
      <origin rpy="0 0 0" xyz="0 0 0"/>
      <geometry>
        <mesh filename="/home/sankalp/ws_spot_catching/src/BimanualDexCatch/assets/urdf/spot_description/meshes/7dof/link4.stl"/>
      </geometry>
    </collision>
    <inertial>
      <origin xyz="-0.00205466 0.07035925 0.01546531"/>
      <mass value="0.96600000"/>
      <inertia ixx="0.00180447" ixy="0.00000423" ixz="0.00000322" iyy="0.00132106" iyz="-0.00029745" izz="0.00211226"/>
    </inertial>
  </link>
  <gazebo reference="robot1/link4">
    <kp>1000000.0</kp>
    <kd>100.0</kd>
    <mu1>30.0</mu1>
    <mu2>30.0</mu2>
    <maxVel>1.0</maxVel>
    <minDepth>0.001</minDepth>
    <material>Gazebo/White</material>
    <selfCollide>1</selfCollide>
    <dampingFactor>0.01</dampingFactor>
  </gazebo>
  <!-- Joint 3 -->
  <joint name="robot1/joint4" type="revolute">
    <parent link="robot1/link4"/>
    <child link="robot1/link5"/>
    <origin rpy="3.141592653589793 -1.5707963267948966 1.5707963267948966" xyz="0.0575 0.10761780185239 0.0300000000000553"/>
    <axis xyz="0 1 0"/>
    <limit effort="100" lower="-3.141592653589793" upper="1.42" velocity="3.03687"/>
    <dynamics damping="0.7"/>
  </joint>
  <transmission name="robot1/tran4">
    <type>transmission_interface/SimpleTransmission</type>
    <joint name="robot1/joint4">
      <hardwareInterface>hardware_interface/PositionJointInterface</hardwareInterface>
    </joint>
    <actuator name="robot1/motor4">
      <mechanicalReduction>1</mechanicalReduction>
    </actuator>
  </transmission>
  <!-- link 5 -->
  <link name="robot1/link5">
    <visual>
      <origin rpy="0 0 3.14" xyz="0.227 0.0085 -0.024"/>
      <geometry>
        <mesh filename="/home/sankalp/ws_spot_catching/src/BimanualDexCatch/assets/urdf/spot_description/meshes/link4_papras.stl" scale="0.001 0.001 0.001"/>
      </geometry>
      <material name="grey"/>
    </visual>
    <collision>
      <origin rpy="0 0 3.14" xyz="0.227 0.0085 -0.024"/>
      <geometry>
        <mesh filename="/home/sankalp/ws_spot_catching/src/BimanualDexCatch/assets/urdf/spot_description/meshes/link5.stl" scale="0.001 0.001 0.001"/>
      </geometry>
    </collision>
    <inertial>
      <origin xyz="0.133722 -0.058143 0.028408"/>
      <!-- <origin xyz="${0.277-0.09327796} 0.06664315 0.05240824" rpy="0 0 3.14"/>                                                                   -->
      <mass value="1.22500000"/>
      <inertia ixx="0.00184346" ixy="0.00000031" ixz="-0.00063174" iyy="0.00588246" iyz="0.00000015" izz="0.00647638"/>
    </inertial>
  </link>
  <gazebo reference="robot1/link5">
    <kp>1000000.0</kp>
    <kd>100.0</kd>
    <mu1>30.0</mu1>
    <mu2>30.0</mu2>
    <maxVel>1.0</maxVel>
    <minDepth>0.001</minDepth>
    <material>Gazebo/White</material>
    <selfCollide>1</selfCollide>
    <dampingFactor>0.01</dampingFactor>
  </gazebo>
  <!-- Joint 4 -->
  <joint name="robot1/joint5" type="revolute">
    <parent link="robot1/link5"/>
    <child link="robot1/link6"/>
    <origin rpy="0 0 0" xyz="0.19500 -0.05750 0.03000"/>
    <axis xyz="1 0 0"/>
    <limit effort="100" lower="-2.748893571891069" upper="2.748893571891069" velocity="3.03687"/>
    <dynamics damping="0.7"/>
  </joint>
  <transmission name="robot1/tran5">
    <type>transmission_interface/SimpleTransmission</type>
    <joint name="robot1/joint5">
      <hardwareInterface>hardware_interface/PositionJointInterface</hardwareInterface>
    </joint>
    <actuator name="robot1/motor5">
      <mechanicalReduction>1</mechanicalReduction>
    </actuator>
  </transmission>
  <!-- link 6 -->
  <link name="robot1/link6">
    <visual>
      <origin rpy="0 0 0" xyz="0 0 0"/>
      <geometry>
        <mesh filename="/home/sankalp/ws_spot_catching/src/BimanualDexCatch/assets/urdf/spot_description/meshes/link5.stl" scale="0.001 0.001 0.001"/>
      </geometry>
      <material name="grey"/>
    </visual>
    <collision>
      <origin rpy="0 0 0" xyz="0 0 0"/>
      <geometry>
        <mesh filename="/home/sankalp/ws_spot_catching/src/BimanualDexCatch/assets/urdf/spot_description/meshes/link6.stl" scale="0.001 0.001 0.001"/>
      </geometry>
    </collision>
    <inertial>
      <origin xyz="0.04029922252 -0.00098556287 -0.00018415947"/>
      <mass value="0.37100000"/>
      <inertia ixx="0.00025425095366" ixy="-0.00000045021116" ixz="-0.00000018765570" iyy="0.00024792762707" iyz="0.00000000815247" izz="0.00038245308001"/>
    </inertial>
  </link>
  <gazebo reference="robot1/link6">
    <kp>1000000.0</kp>
    <kd>100.0</kd>
    <mu1>30.0</mu1>
    <mu2>30.0</mu2>
    <maxVel>1.0</maxVel>
    <minDepth>0.001</minDepth>
    <material>Gazebo/White</material>
    <selfCollide>1</selfCollide>
    <dampingFactor>0.01</dampingFactor>
  </gazebo>
  <!-- Joint 6 -->
  <joint name="robot1/joint6" type="revolute">
    <parent link="robot1/link6"/>
    <child link="robot1/link7"/>
    <origin rpy="0 0 0" xyz="0.06300 0.04500 0.00000"/>
    <axis xyz="0 1 0"/>
    <limit effort="100" lower="-1.5707963267948966" upper="1.5707963267948966" velocity="3.03687"/>
    <dynamics damping="0.7"/>
  </joint>
  <transmission name="robot1/tran6">
    <type>transmission_interface/SimpleTransmission</type>
    <joint name="robot1/joint6">
      <hardwareInterface>hardware_interface/PositionJointInterface</hardwareInterface>
    </joint>
    <actuator name="robot1/motor6">
      <mechanicalReduction>1</mechanicalReduction>
    </actuator>
  </transmission>
  <!-- link 6 -->
  <link name="robot1/link7">
    <visual>
      <origin rpy="0 0 0" xyz="-0.034 -0.098 -0.028"/>
      <geometry>
        <mesh filename="/home/sankalp/ws_spot_catching/src/BimanualDexCatch/assets/urdf/spot_description/meshes/link6_papras.stl" scale="0.001 0.001 0.001"/>
      </geometry>
      <material name="grey"/>
    </visual>
    <collision>
      <origin rpy="0 0 0" xyz="-0.034 -0.098 -0.028"/>
      <geometry>
        <mesh filename="/home/sankalp/ws_spot_catching/src/BimanualDexCatch/assets/urdf/spot_description/meshes/link7.stl" scale="0.001 0.001 0.001"/>
      </geometry>
    </collision>
    <inertial>
      <origin xyz="0.05226593672 -0.04440734021000001 -0.000774351999999999"/>
      <mass value="0.38500000"/>
      <inertia ixx="0.00032088715022" ixy="0.00000000348043" ixz="-0.00000000156396" iyy="0.00056261623134" iyz="-0.00000000024514" izz="0.00074173273605"/>
    </inertial>
  </link>
  <gazebo reference="robot1/link7">
    <kp>1000000.0</kp>
    <kd>100.0</kd>
    <mu1>30.0</mu1>
    <mu2>30.0</mu2>
    <maxVel>1.0</maxVel>
    <minDepth>0.001</minDepth>
    <material>Gazebo/White</material>
    <selfCollide>1</selfCollide>
    <dampingFactor>0.01</dampingFactor>
  </gazebo>
  <!-- Joint 7 -->
  <joint name="robot1/joint7" type="revolute">
    <parent link="robot1/link7"/>
    <child link="robot1/end_link"/>
    <origin rpy="0 0 0" xyz="0.12300 -0.04500 0.00000"/>
    <axis xyz="1 0 0"/>
    <limit effort="100" lower="-3.141592653589793" upper="3.141592653589793" velocity="3.03687"/>
    <dynamics damping="0.7"/>
  </joint>
  <transmission name="robot1/tran7">
    <type>transmission_interface/SimpleTransmission</type>
    <joint name="robot1/joint7">
      <hardwareInterface>hardware_interface/PositionJointInterface</hardwareInterface>
    </joint>
    <actuator name="robot1/motor7">
      <mechanicalReduction>1</mechanicalReduction>
    </actuator>
  </transmission>
  <!-- end link -->
  <link name="robot1/end_link">
    <visual>
      <origin rpy="0 0 0" xyz="0.0 0.0 0.0"/>
      <geometry>
        <mesh filename="/home/sankalp/ws_spot_catching/src/BimanualDexCatch/assets/urdf/spot_description/meshes/end_link.stl" scale="0.001 0.001 0.001"/>
      </geometry>
      <material name="grey"/>
    </visual>
    <collision>
      <origin rpy="0 0 0" xyz="0.0 0.0 0.0"/>
      <geometry>
        <mesh filename="/home/sankalp/ws_spot_catching/src/BimanualDexCatch/assets/urdf/spot_description/meshes/end_link.stl" scale="0.001 0.001 0.001"/>
      </geometry>
    </collision>
    <inertial>
      <origin rpy="0 0 0" xyz="0.00337 0.00000 0.00000"/>
      <mass value="0.01919"/>
      <!-- <inertia ixx="1.0" ixy="0.0" ixz="0.0" iyy="1.0" iyz="0.0" izz="1.0" /> -->
      <inertia ixx="0.00000938" ixy="0.0" ixz="0.0" iyy="0.00000338" iyz="0.0" izz="0.00000635"/>
    </inertial>
  </link>
  <gazebo reference="robot1/end_link">
    <kp>1000000.0</kp>
    <kd>100.0</kd>
    <mu1>30.0</mu1>
    <mu2>30.0</mu2>
    <maxVel>1.0</maxVel>
    <minDepth>0.001</minDepth>
    <material>Gazebo/White</material>
    <selfCollide>1</selfCollide>
    <dampingFactor>0.01</dampingFactor>
  </gazebo>
  <joint name="robot1/end_effector_joint" type="fixed">
    <parent link="robot1/base"/>
    <child link="robot1/end_effector_link"/>
    <origin rpy="0 0 -1.57" xyz="0.0 0.05 0.06"/>
  </joint>
  <!-- End Effector -->
  <link name="robot1/end_effector_link">
    <visual>
      <origin rpy="0 0 0" xyz="0.0 0.0 0.0"/>
      <geometry>
        <box size="0.01 0.01 0.01"/>
      </geometry>
      <material name="red"/>
    </visual>
    <inertial>
      <origin rpy="0 0 0" xyz="0.0 0.0 0.0"/>
      <mass value="0.001"/>
      <inertia ixx="1.0" ixy="0.0" ixz="0.0" iyy="1.0" iyz="0.0" izz="1.0"/>
    </inertial>
  </link>
  <gazebo reference="robot1/end_effector_link">
    <material>Gazebo/Red</material>
  </gazebo>
  <link name="robot1/base">
    <visual name="robot1/wrist_mesh">
      <origin rpy="0 0 0" xyz="0 0 0"/>
      <geometry>
        <mesh filename="/home/sankalp/ws_spot_catching/src/BimanualDexCatch/assets/urdf/spot_description/meshes/psyonic/wristmesh.STL"/>
      </geometry>
    </visual>
    <collision name="robot1/wrist_mesh">
      <origin rpy="0 0 0" xyz="0 0 0"/>
      <geometry>
        <mesh filename="/home/sankalp/ws_spot_catching/src/BimanualDexCatch/assets/urdf/spot_description/meshes/psyonic/wristmesh.STL"/>
      </geometry>
    </collision>
    <inertial>
      <!-- the mass and inertia here are NOT correct -->
      <mass value="0.200"/>
      <inertia ixx="978.26e-6" ixy="87.34e-6" ixz="322.99e-6" iyy="1244.78e-6" iyz="244.74e-6" izz="456.22e-6"/>
      <origin rpy="0 0 0" xyz="22.41911e-3 -0.15798201e-3 -0.01319866e-3"/>
    </inertial>
  </link>
  <joint name="robot1/wrist2thumb" type="fixed">
    <parent link="robot1/base"/>
    <child link="robot1/thumb_base"/>
    <origin rpy="3.14148426 -0.08848813 -3.14036612" xyz="-24.0476665e-3 3.78124745e-3 32.32964923e-3"/>
  </joint>
  <link name="robot1/thumb_base">
    <inertial>
      <mass value="0.200"/>
      <inertia ixx="978.26e-6" ixy="87.34e-6" ixz="322.99e-6" iyy="1244.78e-6" iyz="244.74e-6" izz="456.22e-6"/>
      <origin rpy="0 0 0" xyz="22.41911e-3 -0.15798201e-3 -0.01319866e-3"/>
    </inertial>
    <visual name="robot1/palm_mesh">
      <origin rpy="0 0 0" xyz="0 0 0"/>
      <geometry>
        <mesh filename="/home/sankalp/ws_spot_catching/src/BimanualDexCatch/assets/urdf/spot_description/meshes/psyonic/FB_palm_ref_MIR.STL"/>
      </geometry>
    </visual>
    <collision name="robot1/palm_mesh">
      <origin rpy="0 0 0" xyz="0 0 0"/>
      <geometry>
        <mesh filename="/home/sankalp/ws_spot_catching/src/BimanualDexCatch/assets/urdf/spot_description/meshes/psyonic/FB_palm_ref.STL"/>
      </geometry>
    </collision>
  </link>
  <link name="robot1/index_L1">
    <inertial>
      <mass value="0.00635888"/>
      <inertia ixx="0.29766e-6" ixy="-0.06447133e-6" ixz="-0.00423315e-6" iyy="3.6947967e-6" iyz="0.00083028e-6" izz="3.8176336e-6"/>
      <origin rpy="0 0 0" xyz="22.41911e-3 -0.15798201e-3 -0.01319866e-3"/>
    </inertial>
    <visual name="robot1/index_mesh_1">
      <origin rpy="0 0 0.084474" xyz="38.472723e-3 3.257695e-3 0.000000"/>
      <geometry>
        <mesh filename="/home/sankalp/ws_spot_catching/src/BimanualDexCatch/assets/urdf/spot_description/meshes/psyonic/idx-F1.STL"/>
      </geometry>
    </visual>
    <collision name="robot1/index_mesh_1">
      <origin rpy="0 0 0.084474" xyz="38.472723e-3 3.257695e-3 0.000000"/>
      <geometry>
        <mesh filename="/home/sankalp/ws_spot_catching/src/BimanualDexCatch/assets/urdf/spot_description/meshes/psyonic/idx-F1.STL"/>
      </geometry>
    </collision>
  </link>
  <link name="robot1/index_L2">
    <inertial>
      <mass value="0.00645"/>
      <inertia ixx="0.82671e-6" ixy="-1.08876e-6" ixz="-0.00037e-6" iyy="1.98028e-6" iyz="0.00081e-6" izz="2.64638e-6"/>
      <origin rpy="0 0 0" xyz="13.36818e-3 -8.75392e-3 -0.02886e-3"/>
    </inertial>
    <visual name="robot1/index_mesh_2">
      <origin rpy="0 0 0" xyz="9.1241e-3 0 0"/>
      <geometry>
        <mesh filename="/home/sankalp/ws_spot_catching/src/BimanualDexCatch/assets/urdf/spot_description/meshes/psyonic/idx-F2.STL"/>
      </geometry>
    </visual>
    <collision name="robot1/index_mesh_2">
      <origin rpy="0 0 0" xyz="9.1241e-3 0 0"/>
      <geometry>
        <mesh filename="/home/sankalp/ws_spot_catching/src/BimanualDexCatch/assets/urdf/spot_description/meshes/psyonic/idx-F2.STL"/>
      </geometry>
    </collision>
  </link>
  <joint name="robot1/index_q1" type="revolute">
    <parent link="robot1/thumb_base"/>
    <child link="robot1/index_L1"/>
    <origin rpy=" -1.1595426535897932 1.284473 -1.0510016535897932 " xyz=" 9.49e-3 -13.04e-3 -62.95e-3 "/>
    <axis xyz="0 0 1"/>
    <limit effort="0.20" lower="0" upper="2.0943951" velocity="8.0677777442"/>
    <!-- angles in rad, efforts in N-m, velocity in rad/s -->
    <dynamics damping="0.001" friction="0.001"/>
    <!-- Friction coefficient is not from quantitative measurement -->
  </joint>
  <transmission name="robot1/tran1">
    <type>transmission_interface/SimpleTransmission</type>
    <joint name="robot1/index_q1">
      <hardwareInterface>hardware_interface/PositionJointInterface</hardwareInterface>
    </joint>
    <actuator name="robot1/motor1">
      <mechanicalReduction>1</mechanicalReduction>
    </actuator>
  </transmission>
  <joint name="robot1/index_q2" type="revolute">
    <parent link="robot1/index_L1"/>
    <child link="robot1/index_L2"/>
    <origin rpy="0 0 0.084474" xyz="38.472723e-3 3.257695e-3 0.000000e-3"/>
    <axis xyz="0 0 1"/>
    <limit effort="0.20" lower="0.0" upper="2.6586" velocity="8.0677777442"/>
    <!-- angles in rad, efforts in N-m, velocity in rad/s -->
    <dynamics damping="0.001" friction="0.001"/>
    <!-- Friction coefficient is not from quantitative measurement -->
    <mimic joint="robot1/index_q1" multiplier="1.05851325" offset="0.72349796"/>
  </joint>
  <transmission name="robot1/tran2">
    <type>transmission_interface/SimpleTransmission</type>
    <joint name="robot1/index_q2">
      <hardwareInterface>hardware_interface/PositionJointInterface</hardwareInterface>
    </joint>
    <actuator name="robot1/motor2">
      <mechanicalReduction>1</mechanicalReduction>
    </actuator>
  </transmission>
  <gazebo>
    <!-- loading plugin: mimic joints works in gazebo now -->
    <plugin filename="libroboticsgroup_upatras_gazebo_mimic_joint_plugin.so" name="gazebo_gripper1_ros_control">
      <joint>robot1/index_q1</joint>
      <mimicJoint>robot1/index_q2</mimicJoint>
      <multiplier>1.05851325</multiplier>
      <offset>0.72349796</offset>
    </plugin>
  </gazebo>
  <link name="robot1/index_anchor"/>
  <joint name="robot1/idx_anchor" type="fixed">
    <parent link="robot1/index_L2"/>
    <child link="robot1/index_anchor"/>
    <origin rpy="0 0 0" xyz="31.5541e-3  -10.44e-3 0.14e-3"/>
  </joint>
  <link name="robot1/middle_L1">
    <inertial>
      <mass value="0.00635888"/>
      <inertia ixx="0.29766e-6" ixy="-0.06447133e-6" ixz="-0.00423315e-6" iyy="3.6947967e-6" iyz="0.00083028e-6" izz="3.8176336e-6"/>
      <origin rpy="0 0 0" xyz="22.41911e-3 -0.15798201e-3 -0.01319866e-3"/>
    </inertial>
    <visual name="robot1/middle_mesh_1">
      <origin rpy="0 0 0.084474" xyz="38.472723e-3 3.257695e-3 0.000000"/>
      <geometry>
        <mesh filename="/home/sankalp/ws_spot_catching/src/BimanualDexCatch/assets/urdf/spot_description/meshes/psyonic/idx-F1.STL"/>
      </geometry>
    </visual>
    <collision name="robot1/middle_mesh_1">
      <origin rpy="0 0 0.084474" xyz="38.472723e-3 3.257695e-3 0.000000"/>
      <geometry>
        <mesh filename="/home/sankalp/ws_spot_catching/src/BimanualDexCatch/assets/urdf/spot_description/meshes/psyonic/idx-F1.STL"/>
      </geometry>
    </collision>
  </link>
  <link name="robot1/middle_L2">
    <inertial>
      <mass value="0.00645"/>
      <inertia ixx="0.82671e-6" ixy="-1.08876e-6" ixz="-0.00037e-6" iyy="1.98028e-6" iyz="0.00081e-6" izz="2.64638e-6"/>
      <origin rpy="0 0 0" xyz="13.36818e-3 -8.75392e-3 -0.02886e-3"/>
    </inertial>
    <visual name="robot1/middle_mesh_2">
      <origin rpy="0 0 0" xyz="9.1241e-3 0 0"/>
      <geometry>
        <mesh filename="/home/sankalp/ws_spot_catching/src/BimanualDexCatch/assets/urdf/spot_description/meshes/psyonic/idx-F2.STL"/>
      </geometry>
    </visual>
    <collision name="robot1/middle_mesh_2">
      <origin rpy="0 0 0" xyz="9.1241e-3 0 0"/>
      <geometry>
        <mesh filename="/home/sankalp/ws_spot_catching/src/BimanualDexCatch/assets/urdf/spot_description/meshes/psyonic/idx-F2.STL"/>
      </geometry>
    </collision>
  </link>
  <joint name="robot1/middle_q1" type="revolute">
    <parent link="robot1/thumb_base"/>
    <child link="robot1/middle_L1"/>
    <origin rpy=" -1.2810616535897934 1.308458 -1.2453756535897933 " xyz=" -9.653191e-3 -15.310271e-3 -67.853949e-3 "/>
    <limit effort="0.20" lower="0" upper="2.0943951" velocity="8.0677777442"/>
    <!-- angles in rad, efforts in N-m, velocity in rad/s -->
    <dynamics damping="0.001" friction="0.001"/>
    <!-- Friction coefficient is not from quantitative measurement -->
    <axis xyz="0 0 1"/>
  </joint>
  <transmission name="robot1/tran3">
    <type>transmission_interface/SimpleTransmission</type>
    <joint name="robot1/middle_q1">
      <hardwareInterface>hardware_interface/PositionJointInterface</hardwareInterface>
    </joint>
    <actuator name="robot1/motor3">
      <mechanicalReduction>1</mechanicalReduction>
    </actuator>
  </transmission>
  <joint name="robot1/middle_q2" type="revolute">
    <parent link="robot1/middle_L1"/>
    <child link="robot1/middle_L2"/>
    <origin rpy="0 0 0.084474" xyz="38.472723e-3 3.257695e-3 0.000000"/>
    <axis xyz="0 0 1"/>
    <limit effort="0.20" lower="0.0" upper="2.6586" velocity="8.0677777442"/>
    <!-- angles in rad, efforts in N-m, velocity in rad/s -->
    <dynamics damping="0.001" friction="0.001"/>
    <!-- Friction coefficient is not from quantitative measurement -->
    <mimic joint="robot1/middle_q1" multiplier="1.05851325" offset="0.72349796"/>
  </joint>
  <transmission name="robot1/tran4">
    <type>transmission_interface/SimpleTransmission</type>
    <joint name="robot1/middle_q2">
      <hardwareInterface>hardware_interface/PositionJointInterface</hardwareInterface>
    </joint>
    <actuator name="robot1/motor4">
      <mechanicalReduction>1</mechanicalReduction>
    </actuator>
  </transmission>
  <gazebo>
    <!-- loading plugin: mimic joints works in gazebo now -->
    <plugin filename="libroboticsgroup_upatras_gazebo_mimic_joint_plugin.so" name="gazebo_gripper1_ros_control">
      <joint>robot1/middle_q1</joint>
      <mimicJoint>robot1/middle_q2</mimicJoint>
      <multiplier>1.05851325</multiplier>
      <offset>0.72349796</offset>
    </plugin>
  </gazebo>
  <link name="robot1/middle_anchor"/>
  <joint name="robot1/mid_anchor" type="fixed">
    <parent link="robot1/middle_L2"/>
    <child link="robot1/middle_anchor"/>
    <origin rpy="0 0 0" xyz="31.5541e-3  -10.44e-3 0.14e-3"/>
  </joint>
  <link name="robot1/ring_L1">
    <inertial>
      <mass value="0.00635888"/>
      <inertia ixx="0.29766e-6" ixy="-0.06447133e-6" ixz="-0.00423315e-6" iyy="3.6947967e-6" iyz="0.00083028e-6" izz="3.8176336e-6"/>
      <origin rpy="0 0 0" xyz="22.41911e-3 -0.15798201e-3 -0.01319866e-3"/>
    </inertial>
    <visual name="robot1/ring_mesh_1">
      <origin rpy="0 0 0.084474" xyz="38.472723e-3 3.257695e-3 0.000000"/>
      <geometry>
        <mesh filename="/home/sankalp/ws_spot_catching/src/BimanualDexCatch/assets/urdf/spot_description/meshes/psyonic/idx-F1.STL"/>
      </geometry>
    </visual>
    <collision name="robot1/ring_mesh_1">
      <origin rpy="0 0 0.084474" xyz="38.472723e-3 3.257695e-3 0.000000"/>
      <geometry>
        <mesh filename="/home/sankalp/ws_spot_catching/src/BimanualDexCatch/assets/urdf/spot_description/meshes/psyonic/idx-F1.STL"/>
      </geometry>
    </collision>
  </link>
  <link name="robot1/ring_L2">
    <inertial>
      <mass value="0.00645"/>
      <inertia ixx="0.82671e-6" ixy="-1.08876e-6" ixz="-0.00037e-6" iyy="1.98028e-6" iyz="0.00081e-6" izz="2.64638e-6"/>
      <origin rpy="0 0 0" xyz="13.36818e-3 -8.75392e-3 -0.02886e-3"/>
    </inertial>
    <visual name="robot1/ring_mesh_2">
      <origin rpy="0 0 0" xyz="9.1241e-3 0 0"/>
      <geometry>
        <mesh filename="/home/sankalp/ws_spot_catching/src/BimanualDexCatch/assets/urdf/spot_description/meshes/psyonic/idx-F2.STL"/>
      </geometry>
    </visual>
    <collision name="robot1/ring_mesh_2">
      <origin rpy="0 0 0" xyz="9.1241e-3 0 0"/>
      <geometry>
        <mesh filename="/home/sankalp/ws_spot_catching/src/BimanualDexCatch/assets/urdf/spot_description/meshes/psyonic/idx-F2.STL"/>
      </geometry>
    </collision>
  </link>
  <joint name="robot1/ring_q1" type="revolute">
    <parent link="robot1/thumb_base"/>
    <child link="robot1/ring_L1"/>
    <origin rpy=" -1.424994653589793 1.321452 -1.4657306535897934 " xyz=" -29.95426e-3 -14.212492e-3 -67.286105e-3 "/>
    <limit effort="0.20" lower="0" upper="2.0943951" velocity="8.0677777442"/>
    <!-- angles in rad, efforts in N-m, velocity in rad/s -->
    <dynamics damping="0.001" friction="0.001"/>
    <!-- Friction coefficient is not from quantitative measurement -->
    <axis xyz="0 0 1"/>
  </joint>
  <transmission name="robot1/tran5">
    <type>transmission_interface/SimpleTransmission</type>
    <joint name="robot1/ring_q1">
      <hardwareInterface>hardware_interface/PositionJointInterface</hardwareInterface>
    </joint>
    <actuator name="robot1/motor5">
      <mechanicalReduction>1</mechanicalReduction>
    </actuator>
  </transmission>
  <joint name="robot1/ring_q2" type="revolute">
    <parent link="robot1/ring_L1"/>
    <child link="robot1/ring_L2"/>
    <origin rpy="0 0 0.084474" xyz="38.472723e-3 3.257695e-3 0.000000"/>
    <axis xyz="0 0 1"/>
    <limit effort="0.20" lower="0.0" upper="2.6586" velocity="8.0677777442"/>
    <!-- angles in rad, efforts in N-m, velocity in rad/s -->
    <dynamics damping="0.001" friction="0.001"/>
    <!-- Friction coefficient is not from quantitative measurement -->
    <mimic joint="robot1/ring_q1" multiplier="1.05851325" offset="0.72349796"/>
  </joint>
  <transmission name="robot1/tran6">
    <type>transmission_interface/SimpleTransmission</type>
    <joint name="robot1/ring_q2">
      <hardwareInterface>hardware_interface/PositionJointInterface</hardwareInterface>
    </joint>
    <actuator name="robot1/motor6">
      <mechanicalReduction>1</mechanicalReduction>
    </actuator>
  </transmission>
  <gazebo>
    <!-- loading plugin: mimic joints works in gazebo now -->
    <plugin filename="libroboticsgroup_upatras_gazebo_mimic_joint_plugin.so" name="gazebo_gripper1_ros_control">
      <joint>robot1/ring_q1</joint>
      <mimicJoint>robot1/ring_q2</mimicJoint>
      <multiplier>1.05851325</multiplier>
      <offset>0.72349796</offset>
    </plugin>
  </gazebo>
  <link name="robot1/ring_anchor"/>
  <joint name="robot1/rng_anchor" type="fixed">
    <parent link="robot1/ring_L2"/>
    <child link="robot1/ring_anchor"/>
    <origin rpy="0 0 0" xyz="31.5541e-3  -10.44e-3 0.14e-3"/>
  </joint>
  <link name="robot1/pinky_L1">
    <inertial>
      <mass value="0.00635888"/>
      <inertia ixx="0.29766e-6" ixy="-0.06447133e-6" ixz="-0.00423315e-6" iyy="3.6947967e-6" iyz="0.00083028e-6" izz="3.8176336e-6"/>
      <origin rpy="0 0 0" xyz="22.41911e-3 -0.15798201e-3 -0.01319866e-3"/>
    </inertial>
    <visual name="robot1/pinky_mesh_1">
      <origin rpy="0 0 0.084474" xyz="38.472723e-3 3.257695e-3 0.000000"/>
      <geometry>
        <mesh filename="/home/sankalp/ws_spot_catching/src/BimanualDexCatch/assets/urdf/spot_description/meshes/psyonic/idx-F1.STL"/>
      </geometry>
    </visual>
    <collision name="robot1/pinky_mesh_1">
      <origin rpy="0 0 0.084474" xyz="38.472723e-3 3.257695e-3 0.000000"/>
      <geometry>
        <mesh filename="/home/sankalp/ws_spot_catching/src/BimanualDexCatch/assets/urdf/spot_description/meshes/psyonic/idx-F1.STL"/>
      </geometry>
    </collision>
  </link>
  <link name="robot1/pinky_L2">
    <inertial>
      <mass value="0.00645"/>
      <inertia ixx="0.82671e-6" ixy="-1.08876e-6" ixz="-0.00037e-6" iyy="1.98028e-6" iyz="0.00081e-6" izz="2.64638e-6"/>
      <origin rpy="0 0 0" xyz="13.36818e-3 -8.75392e-3 -0.02886e-3"/>
    </inertial>
    <visual name="robot1/pinky_mesh_2">
      <origin rpy="0 0 0" xyz="9.1241e-3 0 0"/>
      <geometry>
        <mesh filename="/home/sankalp/ws_spot_catching/src/BimanualDexCatch/assets/urdf/spot_description/meshes/psyonic/idx-F2.STL"/>
      </geometry>
    </visual>
    <collision name="robot1/pinky_mesh_2">
      <origin rpy="0 0 0" xyz="9.1241e-3 0 0"/>
      <geometry>
        <mesh filename="/home/sankalp/ws_spot_catching/src/BimanualDexCatch/assets/urdf/spot_description/meshes/psyonic/idx-F2.STL"/>
      </geometry>
    </collision>
  </link>
  <joint name="robot1/pinky_q1" type="revolute">
    <parent link="robot1/thumb_base"/>
    <child link="robot1/pinky_L1"/>
    <origin rpy=" -1.3764826535897934 1.32222 -1.4832096535897932 " xyz=" -49.521293e-3 -11.004583e-3 -63.029065e-3 "/>
    <limit effort="0.20" lower="0" upper="2.0943951" velocity="8.0677777442"/>
    <!-- angles in rad, efforts in N-m, velocity in rad/s -->
    <dynamics damping="0.001" friction="0.001"/>
    <!-- Friction coefficient is not from quantitative measurement -->
    <axis xyz="0 0 1"/>
  </joint>
  <transmission name="robot1/tran7">
    <type>transmission_interface/SimpleTransmission</type>
    <joint name="robot1/pinky_q1">
      <hardwareInterface>hardware_interface/PositionJointInterface</hardwareInterface>
    </joint>
    <actuator name="robot1/motor7">
      <mechanicalReduction>1</mechanicalReduction>
    </actuator>
  </transmission>
  <joint name="robot1/pinky_q2" type="revolute">
    <parent link="robot1/pinky_L1"/>
    <child link="robot1/pinky_L2"/>
    <origin rpy="0 0 0.084474" xyz="38.472723e-3 3.257695e-3 0.000000"/>
    <limit effort="0.20" lower="0.0" upper="2.6586" velocity="8.0677777442"/>
    <!-- angles in rad, efforts in N-m, velocity in rad/s -->
    <dynamics damping="0.001" friction="0.001"/>
    <!-- Friction coefficient is not from quantitative measurement -->
    <axis xyz="0 0 1"/>
    <mimic joint="robot1/pinky_q1" multiplier="1.05851325" offset="0.72349796"/>
  </joint>
  <transmission name="robot1/tran8">
    <type>transmission_interface/SimpleTransmission</type>
    <joint name="robot1/pinky_q2">
      <hardwareInterface>hardware_interface/PositionJointInterface</hardwareInterface>
    </joint>
    <actuator name="robot1/motor8">
      <mechanicalReduction>1</mechanicalReduction>
    </actuator>
  </transmission>
  <gazebo>
    <!-- loading plugin: mimic joints works in gazebo now -->
    <plugin filename="libroboticsgroup_upatras_gazebo_mimic_joint_plugin.so" name="gazebo_gripper1_ros_control">
      <joint>robot1/pinky_q1</joint>
      <mimicJoint>robot1/pinky_q2</mimicJoint>
      <multiplier>1.05851325</multiplier>
      <offset>0.72349796</offset>
    </plugin>
  </gazebo>
  <link name="robot1/pinky_anchor"/>
  <joint name="robot1/pnky_anchor" type="fixed">
    <parent link="robot1/pinky_L2"/>
    <child link="robot1/pinky_anchor"/>
    <origin rpy="0 0 0" xyz="31.5541e-3  -10.44e-3 0.14e-3"/>
  </joint>
  <link name="robot1/thumb_L1">
    <inertial>
      <mass value="0.00268342"/>
      <inertia ixx="0.16931e-6" ixy="-0.076214e-6" ixz="-0.16959148e-6" iyy="0.77769934e-6" iyz="0.0156622e-6" izz="0.7249122e-6"/>
      <origin rpy="0 0 0" xyz="14.606e-3 -1.890854e-3 -3.1155356e-3"/>
    </inertial>
    <visual name="robot1/thumb_mesh_1">
      <origin rpy=" 1.832595714594045 -0.0 5.366520605522463e-18 " xyz=" 27.8283501e-3 1.7436510745838653e-19 14.7507e-3 "/>
      <geometry>
        <mesh filename="/home/sankalp/ws_spot_catching/src/BimanualDexCatch/assets/urdf/spot_description/meshes/psyonic/thumb-F1-MIR.STL"/>
      </geometry>
    </visual>
    <collision name="robot1/thumb_mesh_1">
      <origin rpy=" 1.832595714594045 -0.0 5.366520605522463e-18 " xyz=" 27.8283501e-3 1.7436510745838653e-19 14.7507e-3 "/>
      <geometry>
        <mesh filename="/home/sankalp/ws_spot_catching/src/BimanualDexCatch/assets/urdf/spot_description/meshes/psyonic/thumb-F1-MIR.STL"/>
      </geometry>
    </collision>
  </link>
  <link name="robot1/thumb_L2">
    <inertial>
      <mass value="0.0055"/>
      <inertia ixx="4.4789082e-6" ixy="4.4789082e-6" ixz="-0.62144934e-6" iyy="15.600996e-6" iyz="-0.07466143e-6" izz="17.908554e-6"/>
      <origin rpy="0 0 0" xyz="30.020522e-3 5.59476e-3 -4.1504356e-3"/>
    </inertial>
    <visual name="robot1/thumb_mesh_2">
      <origin rpy="-3.141592 0 0.343830" xyz="65.18669e-3 23.34021e-3 3.93483e-3"/>
      <geometry>
        <mesh filename="/home/sankalp/ws_spot_catching/src/BimanualDexCatch/assets/urdf/spot_description/meshes/psyonic/thumb-F2.STL"/>
      </geometry>
    </visual>
    <collision name="robot1/thumb_mesh_2">
      <origin rpy="-3.141592 0 0.343830" xyz="65.18669e-3 23.34021e-3 3.93483e-3"/>
      <geometry>
        <mesh filename="/home/sankalp/ws_spot_catching/src/BimanualDexCatch/assets/urdf/spot_description/meshes/psyonic/thumb-F2.STL"/>
      </geometry>
    </collision>
  </link>
  <joint name="robot1/thumb_q1" type="revolute">
    <parent link="robot1/thumb_base"/>
    <child link="robot1/thumb_L1"/>
    <origin rpy=" 3.141592653589793 -0.0 -0.18884434641020664 " xyz=" 0.0 0.0 0.0 "/>
    <axis xyz="0 0 1"/>
    <limit effort="0.20" lower="-2.0943951" upper="0" velocity="8.0677777442"/>
    <!-- angles in rad, efforts in N-m, velocity in rad/s -->
    <dynamics damping="0.001" friction="0.001"/>
    <!-- Friction coefficient is not from quantitative measurement -->
  </joint>
  <transmission name="robot1/tran9">
    <type>transmission_interface/SimpleTransmission</type>
    <joint name="robot1/thumb_q1">
      <hardwareInterface>hardware_interface/PositionJointInterface</hardwareInterface>
    </joint>
    <actuator name="robot1/motor9">
      <mechanicalReduction>1</mechanicalReduction>
    </actuator>
  </transmission>
  <joint name="robot1/thumb_q2" type="revolute">
    <parent link="robot1/thumb_L1"/>
    <child link="robot1/thumb_L2"/>
    <origin rpy=" 1.832595714594045 -0.0 5.366520605522463e-18 " xyz=" 27.8283501e-3 1.7436510745838653e-19 14.7507e-3 "/>
    <axis xyz="0 0 1"/>
    <limit effort="0.20" lower="0" upper="2.0943951" velocity="8.0677777442"/>
    <!-- angles in rad, efforts in N-m, velocity in rad/s -->
    <dynamics damping="0.001" friction="0.001"/>
    <!-- Friction coefficient is not from quantitative measurement -->
  </joint>
  <transmission name="robot1/tran10">
    <type>transmission_interface/SimpleTransmission</type>
    <joint name="robot1/thumb_q2">
      <hardwareInterface>hardware_interface/PositionJointInterface</hardwareInterface>
    </joint>
    <actuator name="robot1/motor10">
      <mechanicalReduction>1</mechanicalReduction>
    </actuator>
  </transmission>
  <link name="robot1/thumb_anchor"/>
  <joint name="robot1/thmb_anchor" type="fixed">
    <parent link="robot1/thumb_L2"/>
    <child link="robot1/thumb_anchor"/>
    <origin rpy="0 0 0" xyz="52.00122724e-3 28.00869333e-3 6.98483578e-3"/>
  </joint>
  <joint name="robot1/papras2psyonic" type="fixed">
    <parent link="robot1/end_link"/>
    <child link="robot1/base"/>
    <origin rpy="1.57 0 1.57" xyz="0.005 0 0"/>
  </joint>
  <!-- link 1 -->
  <link name="robot2/link1">
    <visual>
      <origin rpy="0 0 0" xyz="0 0 0"/>
      <geometry>
        <mesh filename="/home/sankalp/ws_spot_catching/src/BimanualDexCatch/assets/urdf/spot_description/meshes/link1.stl" scale="0.001 0.001 0.001"/>
      </geometry>
      <material name="grey"/>
    </visual>
    <collision>
      <origin rpy="0 0 0" xyz="0 0 0"/>
      <geometry>
        <mesh filename="/home/sankalp/ws_spot_catching/src/BimanualDexCatch/assets/urdf/spot_description/meshes/link1.stl" scale="0.001 0.001 0.001"/>
      </geometry>
    </collision>
    <inertial>
      <origin xyz="-0.00205616406 0.00000000 0.07012969338"/>
      <mass value="0.91200000"/>
      <inertia ixx="0.00140582306367" ixy="0.00000000" ixz="0.00000000" iyy="0.00140582097352" iyz="-0.00000000" izz="0.00043779331105"/>
    </inertial>
  </link>
  <gazebo reference="robot2/link1">
    <kp>1000000.0</kp>
    <kd>100.0</kd>
    <mu1>30.0</mu1>
    <mu2>30.0</mu2>
    <maxVel>1.0</maxVel>
    <minDepth>0.001</minDepth>
    <material>Gazebo/White</material>
    <selfCollide>1</selfCollide>
    <dampingFactor>0.01</dampingFactor>
  </gazebo>
  <!-- Joint 1 -->
  <joint name="robot2/joint1" type="revolute">
    <parent link="robot2/link1"/>
    <child link="robot2/link2"/>
    <origin rpy="0 0 0" xyz="0.0 0.0 0.126"/>
    <axis xyz="0 0 1"/>
    <limit effort="100" lower="-3.141592653589793" upper="3.141592653589793" velocity="3.03687"/>
    <dynamics damping="0.7"/>
  </joint>
  <transmission name="robot2/tran1">
    <type>transmission_interface/SimpleTransmission</type>
    <joint name="robot2/joint1">
      <hardwareInterface>hardware_interface/PositionJointInterface</hardwareInterface>
    </joint>
    <actuator name="robot2/motor1">
      <mechanicalReduction>1</mechanicalReduction>
    </actuator>
  </transmission>
  <!-- link 2 -->
  <link name="robot2/link2">
    <visual>
      <origin rpy="0 0 0" xyz="0 0 0"/>
      <geometry>
        <mesh filename="/home/sankalp/ws_spot_catching/src/BimanualDexCatch/assets/urdf/spot_description/meshes/link2.stl" scale="0.001 0.001 0.001"/>
      </geometry>
      <material name="grey"/>
    </visual>
    <collision>
      <origin rpy="0 0 0" xyz="0 0 0"/>
      <geometry>
        <mesh filename="/home/sankalp/ws_spot_catching/src/BimanualDexCatch/assets/urdf/spot_description/meshes/link2.stl" scale="0.001 0.001 0.001"/>
      </geometry>
    </collision>
    <inertial>
      <origin xyz="-0.00000000001 -0.01570756882 0.02819237930"/>
      <mass value="0.88500000"/>
      <inertia ixx="0.00155754725347" ixy="-0.00000000" ixz="-0.00000000" iyy="0.00048405544236" iyz="-0.00000173296990" izz="0.00154667193282"/>
    </inertial>
  </link>
  <gazebo reference="robot2/link2">
    <kp>1000000.0</kp>
    <kd>100.0</kd>
    <mu1>30.0</mu1>
    <mu2>30.0</mu2>
    <maxVel>1.0</maxVel>
    <minDepth>0.001</minDepth>
    <material>Gazebo/White</material>
    <selfCollide>1</selfCollide>
    <dampingFactor>0.01</dampingFactor>
  </gazebo>
  <!-- Joint 2 -->
  <joint name="robot2/joint2" type="revolute">
    <parent link="robot2/link2"/>
    <child link="robot2/link3"/>
    <origin rpy="1.5707963267948966 -1.5707963267948966 0" xyz="0.0 0.00 0.033"/>
    <axis xyz="0 0 1"/>
    <limit effort="100" lower="-2.0" upper="2.0" velocity="3.03687"/>
    <dynamics damping="0.7"/>
  </joint>
  <transmission name="robot2/tran2">
    <type>transmission_interface/SimpleTransmission</type>
    <joint name="robot2/joint2">
      <hardwareInterface>hardware_interface/PositionJointInterface</hardwareInterface>
    </joint>
    <actuator name="robot2/motor2">
      <mechanicalReduction>1</mechanicalReduction>
    </actuator>
  </transmission>
  <!-- link 2 -->
  <link name="robot2/link3">
    <visual>
      <origin rpy="0 0 0" xyz="0.0 0.0 0.0"/>
      <geometry>
        <mesh filename="/home/sankalp/ws_spot_catching/src/BimanualDexCatch/assets/urdf/spot_description/meshes/7dof/link3.stl"/>
      </geometry>
      <material name="grey"/>
    </visual>
    <collision>
      <origin rpy="0 0 0" xyz="0 0 0"/>
      <geometry>
        <mesh filename="/home/sankalp/ws_spot_catching/src/BimanualDexCatch/assets/urdf/spot_description/meshes/7dof/link3.stl"/>
      </geometry>
    </collision>
    <inertial>
      <origin xyz="0.10300488 0.00026160 0.00111164"/>
      <mass value="1.01000000"/>
      <inertia ixx="0.00182373" ixy="-0.00000000" ixz="-0.00000526" iyy="0.00433189" iyz="0.00000000" izz="0.00310084"/>
    </inertial>
  </link>
  <gazebo reference="robot2/link3">
    <kp>1000000.0</kp>
    <kd>100.0</kd>
    <mu1>30.0</mu1>
    <mu2>30.0</mu2>
    <maxVel>1.0</maxVel>
    <minDepth>0.001</minDepth>
    <material>Gazebo/White</material>
    <selfCollide>1</selfCollide>
    <dampingFactor>0.01</dampingFactor>
  </gazebo>
  <!-- Joint 2 -->
  <joint name="robot2/joint3" type="revolute">
    <parent link="robot2/link3"/>
    <child link="robot2/link4"/>
    <origin rpy="0 -1.5707963267948966 -1.5707963267948966" xyz="0.156382198147594 0 0.000400000000010851"/>
    <axis xyz="0 1 0"/>
    <limit effort="100" lower="-3.141592653589793" upper="3.141592653589793" velocity="3.03687"/>
    <dynamics damping="0.7"/>
  </joint>
  <transmission name="robot2/tran3">
    <type>transmission_interface/SimpleTransmission</type>
    <joint name="robot2/joint3">
      <hardwareInterface>hardware_interface/PositionJointInterface</hardwareInterface>
    </joint>
    <actuator name="robot2/motor3">
      <mechanicalReduction>1</mechanicalReduction>
    </actuator>
  </transmission>
  <!-- link 2 -->
  <link name="robot2/link4">
    <visual>
      <origin rpy="0 0 0" xyz="0.0 0.0 0.0"/>
      <geometry>
        <mesh filename="/home/sankalp/ws_spot_catching/src/BimanualDexCatch/assets/urdf/spot_description/meshes/7dof/link4.stl"/>
      </geometry>
      <material name="grey"/>
    </visual>
    <collision>
      <origin rpy="0 0 0" xyz="0 0 0"/>
      <geometry>
        <mesh filename="/home/sankalp/ws_spot_catching/src/BimanualDexCatch/assets/urdf/spot_description/meshes/7dof/link4.stl"/>
      </geometry>
    </collision>
    <inertial>
      <origin xyz="-0.00205466 0.07035925 0.01546531"/>
      <mass value="0.96600000"/>
      <inertia ixx="0.00180447" ixy="0.00000423" ixz="0.00000322" iyy="0.00132106" iyz="-0.00029745" izz="0.00211226"/>
    </inertial>
  </link>
  <gazebo reference="robot2/link4">
    <kp>1000000.0</kp>
    <kd>100.0</kd>
    <mu1>30.0</mu1>
    <mu2>30.0</mu2>
    <maxVel>1.0</maxVel>
    <minDepth>0.001</minDepth>
    <material>Gazebo/White</material>
    <selfCollide>1</selfCollide>
    <dampingFactor>0.01</dampingFactor>
  </gazebo>
  <!-- Joint 3 -->
  <joint name="robot2/joint4" type="revolute">
    <parent link="robot2/link4"/>
    <child link="robot2/link5"/>
    <origin rpy="3.141592653589793 -1.5707963267948966 1.5707963267948966" xyz="0.0575 0.10761780185239 0.0300000000000553"/>
    <axis xyz="0 1 0"/>
    <limit effort="100" lower="-3.141592653589793" upper="1.42" velocity="3.03687"/>
    <dynamics damping="0.7"/>
  </joint>
  <transmission name="robot2/tran4">
    <type>transmission_interface/SimpleTransmission</type>
    <joint name="robot2/joint4">
      <hardwareInterface>hardware_interface/PositionJointInterface</hardwareInterface>
    </joint>
    <actuator name="robot2/motor4">
      <mechanicalReduction>1</mechanicalReduction>
    </actuator>
  </transmission>
  <!-- link 5 -->
  <link name="robot2/link5">
    <visual>
      <origin rpy="0 0 3.14" xyz="0.227 0.0085 -0.024"/>
      <geometry>
        <mesh filename="/home/sankalp/ws_spot_catching/src/BimanualDexCatch/assets/urdf/spot_description/meshes/link4_papras.stl" scale="0.001 0.001 0.001"/>
      </geometry>
      <material name="grey"/>
    </visual>
    <collision>
      <origin rpy="0 0 3.14" xyz="0.227 0.0085 -0.024"/>
      <geometry>
        <mesh filename="/home/sankalp/ws_spot_catching/src/BimanualDexCatch/assets/urdf/spot_description/meshes/link5.stl" scale="0.001 0.001 0.001"/>
      </geometry>
    </collision>
    <inertial>
      <origin xyz="0.133722 -0.058143 0.028408"/>
      <!-- <origin xyz="${0.277-0.09327796} 0.06664315 0.05240824" rpy="0 0 3.14"/>                                                                   -->
      <mass value="1.22500000"/>
      <inertia ixx="0.00184346" ixy="0.00000031" ixz="-0.00063174" iyy="0.00588246" iyz="0.00000015" izz="0.00647638"/>
    </inertial>
  </link>
  <gazebo reference="robot2/link5">
    <kp>1000000.0</kp>
    <kd>100.0</kd>
    <mu1>30.0</mu1>
    <mu2>30.0</mu2>
    <maxVel>1.0</maxVel>
    <minDepth>0.001</minDepth>
    <material>Gazebo/White</material>
    <selfCollide>1</selfCollide>
    <dampingFactor>0.01</dampingFactor>
  </gazebo>
  <!-- Joint 4 -->
  <joint name="robot2/joint5" type="revolute">
    <parent link="robot2/link5"/>
    <child link="robot2/link6"/>
    <origin rpy="0 0 0" xyz="0.19500 -0.05750 0.03000"/>
    <axis xyz="1 0 0"/>
    <limit effort="100" lower="-2.748893571891069" upper="2.748893571891069" velocity="3.03687"/>
    <dynamics damping="0.7"/>
  </joint>
  <transmission name="robot2/tran5">
    <type>transmission_interface/SimpleTransmission</type>
    <joint name="robot2/joint5">
      <hardwareInterface>hardware_interface/PositionJointInterface</hardwareInterface>
    </joint>
    <actuator name="robot2/motor5">
      <mechanicalReduction>1</mechanicalReduction>
    </actuator>
  </transmission>
  <!-- link 6 -->
  <link name="robot2/link6">
    <visual>
      <origin rpy="0 0 0" xyz="0 0 0"/>
      <geometry>
        <mesh filename="/home/sankalp/ws_spot_catching/src/BimanualDexCatch/assets/urdf/spot_description/meshes/link5.stl" scale="0.001 0.001 0.001"/>
      </geometry>
      <material name="grey"/>
    </visual>
    <collision>
      <origin rpy="0 0 0" xyz="0 0 0"/>
      <geometry>
        <mesh filename="/home/sankalp/ws_spot_catching/src/BimanualDexCatch/assets/urdf/spot_description/meshes/link6.stl" scale="0.001 0.001 0.001"/>
      </geometry>
    </collision>
    <inertial>
      <origin xyz="0.04029922252 -0.00098556287 -0.00018415947"/>
      <mass value="0.37100000"/>
      <inertia ixx="0.00025425095366" ixy="-0.00000045021116" ixz="-0.00000018765570" iyy="0.00024792762707" iyz="0.00000000815247" izz="0.00038245308001"/>
    </inertial>
  </link>
  <gazebo reference="robot2/link6">
    <kp>1000000.0</kp>
    <kd>100.0</kd>
    <mu1>30.0</mu1>
    <mu2>30.0</mu2>
    <maxVel>1.0</maxVel>
    <minDepth>0.001</minDepth>
    <material>Gazebo/White</material>
    <selfCollide>1</selfCollide>
    <dampingFactor>0.01</dampingFactor>
  </gazebo>
  <!-- Joint 6 -->
  <joint name="robot2/joint6" type="revolute">
    <parent link="robot2/link6"/>
    <child link="robot2/link7"/>
    <origin rpy="0 0 0" xyz="0.06300 0.04500 0.00000"/>
    <axis xyz="0 1 0"/>
    <limit effort="100" lower="-1.5707963267948966" upper="1.5707963267948966" velocity="3.03687"/>
    <dynamics damping="0.7"/>
  </joint>
  <transmission name="robot2/tran6">
    <type>transmission_interface/SimpleTransmission</type>
    <joint name="robot2/joint6">
      <hardwareInterface>hardware_interface/PositionJointInterface</hardwareInterface>
    </joint>
    <actuator name="robot2/motor6">
      <mechanicalReduction>1</mechanicalReduction>
    </actuator>
  </transmission>
  <!-- link 6 -->
  <link name="robot2/link7">
    <visual>
      <origin rpy="0 0 0" xyz="-0.034 -0.098 -0.028"/>
      <geometry>
        <mesh filename="/home/sankalp/ws_spot_catching/src/BimanualDexCatch/assets/urdf/spot_description/meshes/link6_papras.stl" scale="0.001 0.001 0.001"/>
      </geometry>
      <material name="grey"/>
    </visual>
    <collision>
      <origin rpy="0 0 0" xyz="-0.034 -0.098 -0.028"/>
      <geometry>
        <mesh filename="/home/sankalp/ws_spot_catching/src/BimanualDexCatch/assets/urdf/spot_description/meshes/link7.stl" scale="0.001 0.001 0.001"/>
      </geometry>
    </collision>
    <inertial>
      <origin xyz="0.05226593672 -0.04440734021000001 -0.000774351999999999"/>
      <mass value="0.38500000"/>
      <inertia ixx="0.00032088715022" ixy="0.00000000348043" ixz="-0.00000000156396" iyy="0.00056261623134" iyz="-0.00000000024514" izz="0.00074173273605"/>
    </inertial>
  </link>
  <gazebo reference="robot2/link7">
    <kp>1000000.0</kp>
    <kd>100.0</kd>
    <mu1>30.0</mu1>
    <mu2>30.0</mu2>
    <maxVel>1.0</maxVel>
    <minDepth>0.001</minDepth>
    <material>Gazebo/White</material>
    <selfCollide>1</selfCollide>
    <dampingFactor>0.01</dampingFactor>
  </gazebo>
  <!-- Joint 7 -->
  <joint name="robot2/joint7" type="revolute">
    <parent link="robot2/link7"/>
    <child link="robot2/end_link"/>
    <origin rpy="0 0 0" xyz="0.12300 -0.04500 0.00000"/>
    <axis xyz="1 0 0"/>
    <limit effort="100" lower="-3.141592653589793" upper="3.141592653589793" velocity="3.03687"/>
    <dynamics damping="0.7"/>
  </joint>
  <transmission name="robot2/tran7">
    <type>transmission_interface/SimpleTransmission</type>
    <joint name="robot2/joint7">
      <hardwareInterface>hardware_interface/PositionJointInterface</hardwareInterface>
    </joint>
    <actuator name="robot2/motor7">
      <mechanicalReduction>1</mechanicalReduction>
    </actuator>
  </transmission>
  <!-- end link -->
  <link name="robot2/end_link">
    <visual>
      <origin rpy="0 0 0" xyz="0.0 0.0 0.0"/>
      <geometry>
        <mesh filename="/home/sankalp/ws_spot_catching/src/BimanualDexCatch/assets/urdf/spot_description/meshes/end_link.stl" scale="0.001 0.001 0.001"/>
      </geometry>
      <material name="grey"/>
    </visual>
    <collision>
      <origin rpy="0 0 0" xyz="0.0 0.0 0.0"/>
      <geometry>
        <mesh filename="/home/sankalp/ws_spot_catching/src/BimanualDexCatch/assets/urdf/spot_description/meshes/end_link.stl" scale="0.001 0.001 0.001"/>
      </geometry>
    </collision>
    <inertial>
      <origin rpy="0 0 0" xyz="0.00337 0.00000 0.00000"/>
      <mass value="0.01919"/>
      <!-- <inertia ixx="1.0" ixy="0.0" ixz="0.0" iyy="1.0" iyz="0.0" izz="1.0" /> -->
      <inertia ixx="0.00000938" ixy="0.0" ixz="0.0" iyy="0.00000338" iyz="0.0" izz="0.00000635"/>
    </inertial>
  </link>
  <gazebo reference="robot2/end_link">
    <kp>1000000.0</kp>
    <kd>100.0</kd>
    <mu1>30.0</mu1>
    <mu2>30.0</mu2>
    <maxVel>1.0</maxVel>
    <minDepth>0.001</minDepth>
    <material>Gazebo/White</material>
    <selfCollide>1</selfCollide>
    <dampingFactor>0.01</dampingFactor>
  </gazebo>
  <joint name="robot2/end_effector_joint" type="fixed">
    <parent link="robot2/base"/>
    <child link="robot2/end_effector_link"/>
    <origin rpy="0 0 -1.57" xyz="0.0 0.05 0.06"/>
  </joint>
  <!-- End Effector -->
  <link name="robot2/end_effector_link">
    <visual>
      <origin rpy="0 0 0" xyz="0.0 0.0 0.0"/>
      <geometry>
        <box size="0.01 0.01 0.01"/>
      </geometry>
      <material name="red"/>
    </visual>
    <inertial>
      <origin rpy="0 0 0" xyz="0.0 0.0 0.0"/>
      <mass value="0.001"/>
      <inertia ixx="1.0" ixy="0.0" ixz="0.0" iyy="1.0" iyz="0.0" izz="1.0"/>
    </inertial>
  </link>
  <gazebo reference="robot2/end_effector_link">
    <material>Gazebo/Red</material>
  </gazebo>
  <link name="robot2/base">
    <visual name="robot2/wrist_mesh">
      <origin rpy="0 0 0" xyz="0 0 0"/>
      <geometry>
        <mesh filename="/home/sankalp/ws_spot_catching/src/BimanualDexCatch/assets/urdf/spot_description/meshes/psyonic/wristmesh.STL"/>
      </geometry>
    </visual>
    <collision name="robot2/wrist_mesh">
      <origin rpy="0 0 0" xyz="0 0 0"/>
      <geometry>
        <mesh filename="/home/sankalp/ws_spot_catching/src/BimanualDexCatch/assets/urdf/spot_description/meshes/base.stl"/>
      </geometry>
    </collision>
    <inertial>
      <!-- the mass and inertia here are NOT correct -->
      <mass value="0.200"/>
      <inertia ixx="978.26e-6" ixy="87.34e-6" ixz="322.99e-6" iyy="1244.78e-6" iyz="244.74e-6" izz="456.22e-6"/>
      <origin rpy="0 0 0" xyz="22.41911e-3 -0.15798201e-3 -0.01319866e-3"/>
    </inertial>
  </link>
  <joint name="robot2/wrist2thumb" type="fixed">
    <parent link="robot2/base"/>
    <child link="robot2/thumb_base"/>
    <origin rpy="3.14148426 0.08848813 3.14036612" xyz="24.0476665e-3 3.78124745e-3 32.32964923e-3"/>
  </joint>
  <link name="robot2/thumb_base">
    <inertial>
      <mass value="0.400"/>
      <inertia ixx="978.26e-6" ixy="87.34e-6" ixz="322.99e-6" iyy="1244.78e-6" iyz="244.74e-6" izz="456.22e-6"/>
      <origin rpy="0 0 0" xyz="22.41911e-3 -0.15798201e-3 -0.01319866e-3"/>
    </inertial>
    <visual name="robot2/palm_mesh">
      <origin rpy="0 0 0" xyz="0 0 0"/>
      <geometry>
        <mesh filename="/home/sankalp/ws_spot_catching/src/BimanualDexCatch/assets/urdf/spot_description/meshes/psyonic/FB_palm_ref.STL"/>
      </geometry>
    </visual>
    <collision name="robot2/palm_mesh">
      <origin rpy="0 0 0" xyz="0 0 0"/>
      <geometry>
        <mesh filename="/home/sankalp/ws_spot_catching/src/BimanualDexCatch/assets/urdf/spot_description/meshes/psyonic/FB_palm_ref.STL"/>
      </geometry>
    </collision>
  </link>
  <link name="robot2/index_L1">
    <inertial>
      <mass value="0.00635888"/>
      <inertia ixx="0.29766e-6" ixy="-0.06447133e-6" ixz="-0.00423315e-6" iyy="3.6947967e-6" iyz="0.00083028e-6" izz="3.8176336e-6"/>
      <origin rpy="0 0 0" xyz="22.41911e-3 -0.15798201e-3 -0.01319866e-3"/>
    </inertial>
    <visual name="robot2/index_mesh_1">
      <origin rpy="0 0 0.084474" xyz="38.472723e-3 3.257695e-3 0.000000"/>
      <geometry>
        <mesh filename="/home/sankalp/ws_spot_catching/src/BimanualDexCatch/assets/urdf/spot_description/meshes/psyonic/idx-F1.STL"/>
      </geometry>
    </visual>
    <collision name="robot2/index_mesh_1">
      <origin rpy="0 0 0.084474" xyz="38.472723e-3 3.257695e-3 0.000000"/>
      <geometry>
        <mesh filename="/home/sankalp/ws_spot_catching/src/BimanualDexCatch/assets/urdf/spot_description/meshes/psyonic/idx-F1.STL"/>
      </geometry>
    </collision>
  </link>
  <link name="robot2/index_L2">
    <inertial>
      <mass value="0.00645"/>
      <inertia ixx="0.82671e-6" ixy="-1.08876e-6" ixz="-0.00037e-6" iyy="1.98028e-6" iyz="0.00081e-6" izz="2.64638e-6"/>
      <origin rpy="0 0 0" xyz="13.36818e-3 -8.75392e-3 -0.02886e-3"/>
    </inertial>
    <visual name="robot2/index_mesh_2">
      <origin rpy="0 0 0" xyz="9.1241e-3 0 0"/>
      <geometry>
        <mesh filename="/home/sankalp/ws_spot_catching/src/BimanualDexCatch/assets/urdf/spot_description/meshes/psyonic/idx-F2.STL"/>
      </geometry>
    </visual>
    <collision name="robot2/index_mesh_2">
      <origin rpy="0 0 0" xyz="9.1241e-3 0 0"/>
      <geometry>
        <mesh filename="/home/sankalp/ws_spot_catching/src/BimanualDexCatch/assets/urdf/spot_description/meshes/psyonic/idx-F2.STL"/>
      </geometry>
    </collision>
  </link>
  <joint name="robot2/index_q1" type="revolute">
    <parent link="robot2/thumb_base"/>
    <child link="robot2/index_L1"/>
    <origin rpy="-1.982050 1.284473 -2.090591" xyz="-9.49e-3 -13.04e-3 -62.95e-3"/>
    <axis xyz="0 0 1"/>
    <limit effort="0.20" lower="0" upper="2.0943951" velocity="8.0677777442"/>
    <!-- angles in rad, efforts in N-m, velocity in rad/s -->
    <dynamics damping="0.001" friction="0.001"/>
    <!-- Friction coefficient is not from quantitative measurement -->
  </joint>
  <transmission name="robot2/tran11">
    <type>transmission_interface/SimpleTransmission</type>
    <joint name="robot2/index_q1">
      <hardwareInterface>hardware_interface/PositionJointInterface</hardwareInterface>
    </joint>
    <actuator name="robot2/motor11">
      <mechanicalReduction>1</mechanicalReduction>
    </actuator>
  </transmission>
  <joint name="robot2/index_q2" type="revolute">
    <parent link="robot2/index_L1"/>
    <child link="robot2/index_L2"/>
    <origin rpy="0 0 0.084474" xyz="38.472723e-3 3.257695e-3 0.000000e-3"/>
    <axis xyz="0 0 1"/>
    <limit effort="0.20" lower="0.0" upper="2.6586" velocity="8.0677777442"/>
    <!-- angles in rad, efforts in N-m, velocity in rad/s -->
    <dynamics damping="0.001" friction="0.001"/>
    <!-- Friction coefficient is not from quantitative measurement -->
    <mimic joint="robot2/index_q1" multiplier="1.05851325" offset="0.72349796"/>
  </joint>
  <transmission name="robot2/tran12">
    <type>transmission_interface/SimpleTransmission</type>
    <joint name="robot2/index_q2">
      <hardwareInterface>hardware_interface/PositionJointInterface</hardwareInterface>
    </joint>
    <actuator name="robot2/motor12">
      <mechanicalReduction>1</mechanicalReduction>
    </actuator>
  </transmission>
  <gazebo>
    <!-- loading plugin: mimic joints works in gazebo now -->
    <plugin filename="libroboticsgroup_upatras_gazebo_mimic_joint_plugin.so" name="gazebo_gripper2_ros_control">
      <joint>robot2/index_q1</joint>
      <mimicJoint>robot2/index_q2</mimicJoint>
      <multiplier>1.05851325</multiplier>
      <offset>0.72349796</offset>
    </plugin>
  </gazebo>
  <link name="robot2/index_anchor"/>
  <joint name="robot2/idx_anchor" type="fixed">
    <parent link="robot2/index_L2"/>
    <child link="robot2/index_anchor"/>
    <origin rpy="0 0 0" xyz="31.5541e-3  -10.44e-3 0.14e-3"/>
  </joint>
  <link name="robot2/middle_L1">
    <inertial>
      <mass value="0.00635888"/>
      <inertia ixx="0.29766e-6" ixy="-0.06447133e-6" ixz="-0.00423315e-6" iyy="3.6947967e-6" iyz="0.00083028e-6" izz="3.8176336e-6"/>
      <origin rpy="0 0 0" xyz="22.41911e-3 -0.15798201e-3 -0.01319866e-3"/>
    </inertial>
    <visual name="robot2/middle_mesh_1">
      <origin rpy="0 0 0.084474" xyz="38.472723e-3 3.257695e-3 0.000000"/>
      <geometry>
        <mesh filename="/home/sankalp/ws_spot_catching/src/BimanualDexCatch/assets/urdf/spot_description/meshes/psyonic/idx-F1.STL"/>
      </geometry>
    </visual>
    <collision name="robot2/middle_mesh_1">
      <origin rpy="0 0 0.084474" xyz="38.472723e-3 3.257695e-3 0.000000"/>
      <geometry>
        <mesh filename="/home/sankalp/ws_spot_catching/src/BimanualDexCatch/assets/urdf/spot_description/meshes/psyonic/idx-F1.STL"/>
      </geometry>
    </collision>
  </link>
  <link name="robot2/middle_L2">
    <inertial>
      <mass value="0.00645"/>
      <inertia ixx="0.82671e-6" ixy="-1.08876e-6" ixz="-0.00037e-6" iyy="1.98028e-6" iyz="0.00081e-6" izz="2.64638e-6"/>
      <origin rpy="0 0 0" xyz="13.36818e-3 -8.75392e-3 -0.02886e-3"/>
    </inertial>
    <visual name="robot2/middle_mesh_2">
      <origin rpy="0 0 0" xyz="9.1241e-3 0 0"/>
      <geometry>
        <mesh filename="/home/sankalp/ws_spot_catching/src/BimanualDexCatch/assets/urdf/spot_description/meshes/psyonic/idx-F2.STL"/>
      </geometry>
    </visual>
    <collision name="robot2/middle_mesh_2">
      <origin rpy="0 0 0" xyz="9.1241e-3 0 0"/>
      <geometry>
        <mesh filename="/home/sankalp/ws_spot_catching/src/BimanualDexCatch/assets/urdf/spot_description/meshes/psyonic/idx-F2.STL"/>
      </geometry>
    </collision>
  </link>
  <joint name="robot2/middle_q1" type="revolute">
    <parent link="robot2/thumb_base"/>
    <child link="robot2/middle_L1"/>
    <origin rpy="-1.860531 1.308458 -1.896217" xyz="9.653191e-3 -15.310271e-3 -67.853949e-3"/>
    <limit effort="0.20" lower="0" upper="2.0943951" velocity="8.0677777442"/>
    <!-- angles in rad, efforts in N-m, velocity in rad/s -->
    <dynamics damping="0.001" friction="0.001"/>
    <!-- Friction coefficient is not from quantitative measurement -->
    <axis xyz="0 0 1"/>
  </joint>
  <transmission name="robot2/tran13">
    <type>transmission_interface/SimpleTransmission</type>
    <joint name="robot2/middle_q1">
      <hardwareInterface>hardware_interface/PositionJointInterface</hardwareInterface>
    </joint>
    <actuator name="robot2/motor13">
      <mechanicalReduction>1</mechanicalReduction>
    </actuator>
  </transmission>
  <joint name="robot2/middle_q2" type="revolute">
    <parent link="robot2/middle_L1"/>
    <child link="robot2/middle_L2"/>
    <origin rpy="0 0 0.084474" xyz="38.472723e-3 3.257695e-3 0.000000"/>
    <axis xyz="0 0 1"/>
    <limit effort="0.20" lower="0.0" upper="2.6586" velocity="8.0677777442"/>
    <!-- angles in rad, efforts in N-m, velocity in rad/s -->
    <dynamics damping="0.001" friction="0.001"/>
    <!-- Friction coefficient is not from quantitative measurement -->
    <mimic joint="robot2/middle_q1" multiplier="1.05851325" offset="0.72349796"/>
  </joint>
  <transmission name="robot2/tran14">
    <type>transmission_interface/SimpleTransmission</type>
    <joint name="robot2/middle_q2">
      <hardwareInterface>hardware_interface/PositionJointInterface</hardwareInterface>
    </joint>
    <actuator name="robot2/motor14">
      <mechanicalReduction>1</mechanicalReduction>
    </actuator>
  </transmission>
  <gazebo>
    <!-- loading plugin: mimic joints works in gazebo now -->
    <plugin filename="libroboticsgroup_upatras_gazebo_mimic_joint_plugin.so" name="gazebo_gripper2_ros_control">
      <joint>robot2/middle_q1</joint>
      <mimicJoint>robot2/middle_q2</mimicJoint>
      <multiplier>1.05851325</multiplier>
      <offset>0.72349796</offset>
    </plugin>
  </gazebo>
  <link name="robot2/middle_anchor"/>
  <joint name="robot2/mid_anchor" type="fixed">
    <parent link="robot2/middle_L2"/>
    <child link="robot2/middle_anchor"/>
    <origin rpy="0 0 0" xyz="31.5541e-3  -10.44e-3 0.14e-3"/>
  </joint>
  <link name="robot2/ring_L1">
    <inertial>
      <mass value="0.00635888"/>
      <inertia ixx="0.29766e-6" ixy="-0.06447133e-6" ixz="-0.00423315e-6" iyy="3.6947967e-6" iyz="0.00083028e-6" izz="3.8176336e-6"/>
      <origin rpy="0 0 0" xyz="22.41911e-3 -0.15798201e-3 -0.01319866e-3"/>
    </inertial>
    <visual name="robot2/ring_mesh_1">
      <origin rpy="0 0 0.084474" xyz="38.472723e-3 3.257695e-3 0.000000"/>
      <geometry>
        <mesh filename="/home/sankalp/ws_spot_catching/src/BimanualDexCatch/assets/urdf/spot_description/meshes/psyonic/idx-F1.STL"/>
      </geometry>
    </visual>
    <collision name="robot2/ring_mesh_1">
      <origin rpy="0 0 0.084474" xyz="38.472723e-3 3.257695e-3 0.000000"/>
      <geometry>
        <mesh filename="/home/sankalp/ws_spot_catching/src/BimanualDexCatch/assets/urdf/spot_description/meshes/psyonic/idx-F1.STL"/>
      </geometry>
    </collision>
  </link>
  <link name="robot2/ring_L2">
    <inertial>
      <mass value="0.00645"/>
      <inertia ixx="0.82671e-6" ixy="-1.08876e-6" ixz="-0.00037e-6" iyy="1.98028e-6" iyz="0.00081e-6" izz="2.64638e-6"/>
      <origin rpy="0 0 0" xyz="13.36818e-3 -8.75392e-3 -0.02886e-3"/>
    </inertial>
    <visual name="robot2/ring_mesh_2">
      <origin rpy="0 0 0" xyz="9.1241e-3 0 0"/>
      <geometry>
        <mesh filename="/home/sankalp/ws_spot_catching/src/BimanualDexCatch/assets/urdf/spot_description/meshes/psyonic/idx-F2.STL"/>
      </geometry>
    </visual>
    <collision name="robot2/ring_mesh_2">
      <origin rpy="0 0 0" xyz="9.1241e-3 0 0"/>
      <geometry>
        <mesh filename="/home/sankalp/ws_spot_catching/src/BimanualDexCatch/assets/urdf/spot_description/meshes/psyonic/idx-F2.STL"/>
      </geometry>
    </collision>
  </link>
  <joint name="robot2/ring_q1" type="revolute">
    <parent link="robot2/thumb_base"/>
    <child link="robot2/ring_L1"/>
    <origin rpy="-1.716598 1.321452 -1.675862" xyz="29.954260e-3 -14.212492e-3 -67.286105e-3"/>
    <limit effort="0.20" lower="0" upper="2.0943951" velocity="8.0677777442"/>
    <!-- angles in rad, efforts in N-m, velocity in rad/s -->
    <dynamics damping="0.001" friction="0.001"/>
    <!-- Friction coefficient is not from quantitative measurement -->
    <axis xyz="0 0 1"/>
  </joint>
  <transmission name="robot2/tran15">
    <type>transmission_interface/SimpleTransmission</type>
    <joint name="robot2/ring_q1">
      <hardwareInterface>hardware_interface/PositionJointInterface</hardwareInterface>
    </joint>
    <actuator name="robot2/motor15">
      <mechanicalReduction>1</mechanicalReduction>
    </actuator>
  </transmission>
  <joint name="robot2/ring_q2" type="revolute">
    <parent link="robot2/ring_L1"/>
    <child link="robot2/ring_L2"/>
    <origin rpy="0 0 0.084474" xyz="38.472723e-3 3.257695e-3 0.000000"/>
    <axis xyz="0 0 1"/>
    <limit effort="0.20" lower="0.0" upper="2.6586" velocity="8.0677777442"/>
    <!-- angles in rad, efforts in N-m, velocity in rad/s -->
    <dynamics damping="0.001" friction="0.001"/>
    <!-- Friction coefficient is not from quantitative measurement -->
    <mimic joint="robot2/ring_q1" multiplier="1.05851325" offset="0.72349796"/>
  </joint>
  <transmission name="robot2/tran16">
    <type>transmission_interface/SimpleTransmission</type>
    <joint name="robot2/ring_q2">
      <hardwareInterface>hardware_interface/PositionJointInterface</hardwareInterface>
    </joint>
    <actuator name="robot2/motor16">
      <mechanicalReduction>1</mechanicalReduction>
    </actuator>
  </transmission>
  <gazebo>
    <!-- loading plugin: mimic joints works in gazebo now -->
    <plugin filename="libroboticsgroup_upatras_gazebo_mimic_joint_plugin.so" name="gazebo_gripper2_ros_control">
      <joint>robot2/ring_q1</joint>
      <mimicJoint>robot2/ring_q2</mimicJoint>
      <multiplier>1.05851325</multiplier>
      <offset>0.72349796</offset>
    </plugin>
  </gazebo>
  <link name="robot2/ring_anchor"/>
  <joint name="robot2/rng_anchor" type="fixed">
    <parent link="robot2/ring_L2"/>
    <child link="robot2/ring_anchor"/>
    <origin rpy="0 0 0" xyz="31.5541e-3  -10.44e-3 0.14e-3"/>
  </joint>
  <link name="robot2/pinky_L1">
    <inertial>
      <mass value="0.00635888"/>
      <inertia ixx="0.29766e-6" ixy="-0.06447133e-6" ixz="-0.00423315e-6" iyy="3.6947967e-6" iyz="0.00083028e-6" izz="3.8176336e-6"/>
      <origin rpy="0 0 0" xyz="22.41911e-3 -0.15798201e-3 -0.01319866e-3"/>
    </inertial>
    <visual name="robot2/pinky_mesh_1">
      <origin rpy="0 0 0.084474" xyz="38.472723e-3 3.257695e-3 0.000000"/>
      <geometry>
        <mesh filename="/home/sankalp/ws_spot_catching/src/BimanualDexCatch/assets/urdf/spot_description/meshes/psyonic/idx-F1.STL"/>
      </geometry>
    </visual>
    <collision name="robot2/pinky_mesh_1">
      <origin rpy="0 0 0.084474" xyz="38.472723e-3 3.257695e-3 0.000000"/>
      <geometry>
        <mesh filename="/home/sankalp/ws_spot_catching/src/BimanualDexCatch/assets/urdf/spot_description/meshes/psyonic/idx-F1.STL"/>
      </geometry>
    </collision>
  </link>
  <link name="robot2/pinky_L2">
    <inertial>
      <mass value="0.00645"/>
      <inertia ixx="0.82671e-6" ixy="-1.08876e-6" ixz="-0.00037e-6" iyy="1.98028e-6" iyz="0.00081e-6" izz="2.64638e-6"/>
      <origin rpy="0 0 0" xyz="13.36818e-3 -8.75392e-3 -0.02886e-3"/>
    </inertial>
    <visual name="robot2/pinky_mesh_2">
      <origin rpy="0 0 0" xyz="9.1241e-3 0 0"/>
      <geometry>
        <mesh filename="/home/sankalp/ws_spot_catching/src/BimanualDexCatch/assets/urdf/spot_description/meshes/psyonic/idx-F2.STL"/>
      </geometry>
    </visual>
    <collision name="robot2/pinky_mesh_2">
      <origin rpy="0 0 0" xyz="9.1241e-3 0 0"/>
      <geometry>
        <mesh filename="/home/sankalp/ws_spot_catching/src/BimanualDexCatch/assets/urdf/spot_description/meshes/psyonic/idx-F2.STL"/>
      </geometry>
    </collision>
  </link>
  <joint name="robot2/pinky_q1" type="revolute">
    <parent link="robot2/thumb_base"/>
    <child link="robot2/pinky_L1"/>
    <origin rpy="-1.765110 1.322220 -1.658383" xyz="49.521293e-3 -11.004583e-3 -63.029065e-3"/>
    <limit effort="0.20" lower="0" upper="2.0943951" velocity="8.0677777442"/>
    <!-- angles in rad, efforts in N-m, velocity in rad/s -->
    <dynamics damping="0.001" friction="0.001"/>
    <!-- Friction coefficient is not from quantitative measurement -->
    <axis xyz="0 0 1"/>
  </joint>
  <transmission name="robot2/tran17">
    <type>transmission_interface/SimpleTransmission</type>
    <joint name="robot2/pinky_q1">
      <hardwareInterface>hardware_interface/PositionJointInterface</hardwareInterface>
    </joint>
    <actuator name="robot2/motor17">
      <mechanicalReduction>1</mechanicalReduction>
    </actuator>
  </transmission>
  <joint name="robot2/pinky_q2" type="revolute">
    <parent link="robot2/pinky_L1"/>
    <child link="robot2/pinky_L2"/>
    <origin rpy="0 0 0.084474" xyz="38.472723e-3 3.257695e-3 0.000000"/>
    <limit effort="0.20" lower="0.0" upper="2.6586" velocity="8.0677777442"/>
    <!-- angles in rad, efforts in N-m, velocity in rad/s -->
    <dynamics damping="0.001" friction="0.001"/>
    <!-- Friction coefficient is not from quantitative measurement -->
    <axis xyz="0 0 1"/>
    <mimic joint="robot2/pinky_q1" multiplier="1.05851325" offset="0.72349796"/>
  </joint>
  <transmission name="robot2/tran18">
    <type>transmission_interface/SimpleTransmission</type>
    <joint name="robot2/pinky_q2">
      <hardwareInterface>hardware_interface/PositionJointInterface</hardwareInterface>
    </joint>
    <actuator name="robot2/motor18">
      <mechanicalReduction>1</mechanicalReduction>
    </actuator>
  </transmission>
  <gazebo>
    <!-- loading plugin: mimic joints works in gazebo now -->
    <plugin filename="libroboticsgroup_upatras_gazebo_mimic_joint_plugin.so" name="gazebo_gripper2_ros_control">
      <joint>robot2/pinky_q1</joint>
      <mimicJoint>robot2/pinky_q2</mimicJoint>
      <multiplier>1.05851325</multiplier>
      <offset>0.72349796</offset>
    </plugin>
  </gazebo>
  <link name="robot2/pinky_anchor"/>
  <joint name="robot2/pnky_anchor" type="fixed">
    <parent link="robot2/pinky_L2"/>
    <child link="robot2/pinky_anchor"/>
    <origin rpy="0 0 0" xyz="31.5541e-3  -10.44e-3 0.14e-3"/>
  </joint>
  <link name="robot2/thumb_L1">
    <inertial>
      <mass value="0.00268342"/>
      <inertia ixx="0.16931e-6" ixy="-0.076214e-6" ixz="-0.16959148e-6" iyy="0.77769934e-6" iyz="0.0156622e-6" izz="0.7249122e-6"/>
      <origin rpy="0 0 0" xyz="14.606e-3 -1.890854e-3 -3.1155356e-3"/>
    </inertial>
    <visual name="robot2/thumb_mesh_1">
      <origin rpy="4.450589592585541 0 0" xyz="27.8283501e-3 0 -14.7507000e-3"/>
      <geometry>
        <mesh filename="/home/sankalp/ws_spot_catching/src/BimanualDexCatch/assets/urdf/spot_description/meshes/psyonic/thumb-F1.STL"/>
      </geometry>
    </visual>
    <collision name="robot2/thumb_mesh_1">
      <origin rpy="4.450589592585541 0 0" xyz="27.8283501e-3 0 -14.7507000e-3"/>
      <geometry>
        <mesh filename="/home/sankalp/ws_spot_catching/src/BimanualDexCatch/assets/urdf/spot_description/meshes/psyonic/thumb-F1.STL"/>
      </geometry>
    </collision>
  </link>
  <link name="robot2/thumb_L2">
    <inertial>
      <mass value="0.0055"/>
      <inertia ixx="4.4789082e-6" ixy="4.4789082e-6" ixz="-0.62144934e-6" iyy="15.600996e-6" iyz="-0.07466143e-6" izz="17.908554e-6"/>
      <origin rpy="0 0 0" xyz="30.020522e-3 5.59476e-3 -4.1504356e-3"/>
    </inertial>
    <visual name="robot2/thumb_mesh_2">
      <origin rpy="3.141592 0 0.343830" xyz="65.18669e-3 23.34021e-3 -3.93483e-3"/>
      <geometry>
        <mesh filename="/home/sankalp/ws_spot_catching/src/BimanualDexCatch/assets/urdf/spot_description/meshes/psyonic/thumb-F2.STL"/>
      </geometry>
    </visual>
    <collision name="robot2/thumb_mesh_2">
      <origin rpy="3.141592 0 0.343830" xyz="65.18669e-3 23.34021e-3 -3.93483e-3"/>
      <geometry>
        <mesh filename="/home/sankalp/ws_spot_catching/src/BimanualDexCatch/assets/urdf/spot_description/meshes/psyonic/thumb-F2.STL"/>
      </geometry>
    </collision>
  </link>
  <joint name="robot2/thumb_q1" type="revolute">
    <parent link="robot2/thumb_base"/>
    <child link="robot2/thumb_L1"/>
    <origin rpy="0 0 3.330437" xyz="0 0 0"/>
    <axis xyz="0 0 1"/>
    <limit effort="0.20" lower="-2.0943951" upper="0" velocity="8.0677777442"/>
    <!-- angles in rad, efforts in N-m, velocity in rad/s -->
    <dynamics damping="0.001" friction="0.001"/>
    <!-- Friction coefficient is not from quantitative measurement -->
  </joint>
  <transmission name="robot2/tran19">
    <type>transmission_interface/SimpleTransmission</type>
    <joint name="robot2/thumb_q1">
      <hardwareInterface>hardware_interface/PositionJointInterface</hardwareInterface>
    </joint>
    <actuator name="robot2/motor19">
      <mechanicalReduction>1</mechanicalReduction>
    </actuator>
  </transmission>
  <joint name="robot2/thumb_q2" type="revolute">
    <parent link="robot2/thumb_L1"/>
    <child link="robot2/thumb_L2"/>
    <origin rpy="4.450589592585541 0 0" xyz="27.8283501e-3 0 -14.7507000e-3"/>
    <axis xyz="0 0 1"/>
    <limit effort="0.20" lower="0" upper="2.0943951" velocity="8.0677777442"/>
    <!-- angles in rad, efforts in N-m, velocity in rad/s -->
    <dynamics damping="0.001" friction="0.001"/>
    <!-- Friction coefficient is not from quantitative measurement -->
  </joint>
  <transmission name="robot2/tran20">
    <type>transmission_interface/SimpleTransmission</type>
    <joint name="robot2/thumb_q2">
      <hardwareInterface>hardware_interface/PositionJointInterface</hardwareInterface>
    </joint>
    <actuator name="robot2/motor20">
      <mechanicalReduction>1</mechanicalReduction>
    </actuator>
  </transmission>
  <link name="robot2/thumb_anchor"/>
  <joint name="robot2/thmb_anchor" type="fixed">
    <parent link="robot2/thumb_L2"/>
    <child link="robot2/thumb_anchor"/>
    <origin rpy="0 0 0" xyz="52.0012259e-3  28.0086971e-3 -.884835778e-3"/>
  </joint>
  <joint name="robot2/papras2psyonic" type="fixed">
    <parent link="robot2/end_link"/>
    <child link="robot2/base"/>
    <origin rpy="1.57 0 1.57" xyz="0.005 0 0"/>
  </joint>
  <!-- Joints -->
  <joint name="robot1/link2_middle_joint" type="fixed">
    <parent link="robot1/link2"/>
    <child link="robot1/link2_middle"/>
    <origin rpy="0 0 0" xyz="0.0 0.0 0"/>
  </joint>
  <link name="robot1/link2_middle"/>
  <joint name="robot1/link3_middle_joint" type="fixed">
    <parent link="robot1/link3"/>
    <child link="robot1/link3_middle"/>
    <origin rpy="0 0 0" xyz="0.06 0.0 0"/>
  </joint>
  <link name="robot1/link3_middle"/>
  <joint name="robot1/link4_middle_joint" type="fixed">
    <parent link="robot1/link4"/>
    <child link="robot1/link4_middle"/>
    <origin rpy="0 0 0" xyz="0.0 0.0 0"/>
  </joint>
  <link name="robot1/link4_middle"/>
  <joint name="robot1/link5_middle_joint" type="fixed">
    <parent link="robot1/link5"/>
    <child link="robot1/link5_middle"/>
    <origin rpy="0 0 0" xyz="0 -0.0575  0"/>
  </joint>
  <link name="robot1/link5_middle"/>
  <joint name="robot1/link6_middle_joint" type="fixed">
    <parent link="robot1/link6"/>
    <child link="robot1/link6_middle"/>
    <origin rpy="0 0 0" xyz="0.03 0 0"/>
  </joint>
  <link name="robot1/link6_middle"/>
  <!-- Joints -->
  <joint name="robot2/link2_middle_joint" type="fixed">
    <parent link="robot2/link2"/>
    <child link="robot2/link2_middle"/>
    <origin rpy="0 0 0" xyz="0.0 0.0 0"/>
  </joint>
  <link name="robot2/link2_middle"/>
  <joint name="robot2/link3_middle_joint" type="fixed">
    <parent link="robot2/link3"/>
    <child link="robot2/link3_middle"/>
    <origin rpy="0 0 0" xyz="0.06 0.0 0"/>
  </joint>
  <link name="robot2/link3_middle"/>
  <joint name="robot2/link4_middle_joint" type="fixed">
    <parent link="robot2/link4"/>
    <child link="robot2/link4_middle"/>
    <origin rpy="0 0 0" xyz="0.0 0.0 0"/>
  </joint>
  <link name="robot2/link4_middle"/>
  <joint name="robot2/link5_middle_joint" type="fixed">
    <parent link="robot2/link5"/>
    <child link="robot2/link5_middle"/>
    <origin rpy="0 0 0" xyz="0 -0.0575  0"/>
  </joint>
  <link name="robot2/link5_middle"/>
  <joint name="robot2/link6_middle_joint" type="fixed">
    <parent link="robot2/link6"/>
    <child link="robot2/link6_middle"/>
    <origin rpy="0 0 0" xyz="0.03 0 0"/>
  </joint>
  <link name="robot2/link6_middle"/>
</robot>

